package cn.gtcommunity.epimorphism.common.metatileentities.multiblock;

import cn.gtcommunity.epimorphism.api.EPAPI;
import cn.gtcommunity.epimorphism.api.block.impl.WrappedIntTier;
import cn.gtcommunity.epimorphism.api.capability.EPDataCode;
import cn.gtcommunity.epimorphism.api.pattern.EPTraceabilityPredicate;
import cn.gtcommunity.epimorphism.api.recipe.EPRecipeMaps;
import cn.gtcommunity.epimorphism.api.utils.EPUniverUtil;
import cn.gtcommunity.epimorphism.client.renderer.texture.EPTextures;
import cn.gtcommunity.epimorphism.common.blocks.EPBlockGlassCasingB;
import cn.gtcommunity.epimorphism.common.blocks.EPBlockQuantumForceTransformerCasing;
import cn.gtcommunity.epimorphism.common.blocks.EPMetablocks;
import cn.gtcommunity.epimorphism.common.metatileentities.EPMetaTileEntities;
import gregtech.api.metatileentity.MetaTileEntity;
import gregtech.api.metatileentity.interfaces.IGregTechTileEntity;
import gregtech.api.metatileentity.multiblock.IMultiblockPart;
import gregtech.api.metatileentity.multiblock.RecipeMapMultiblockController;
import gregtech.api.pattern.BlockPattern;
import gregtech.api.pattern.FactoryBlockPattern;
import gregtech.api.pattern.MultiblockShapeInfo;
import gregtech.api.pattern.PatternMatchContext;
import gregtech.client.renderer.ICubeRenderer;
import gregtech.common.metatileentities.MetaTileEntities;
import net.minecraft.block.state.IBlockState;
import net.minecraft.client.resources.I18n;
import net.minecraft.init.Blocks;
import net.minecraft.item.ItemStack;
import net.minecraft.network.PacketBuffer;
import net.minecraft.util.EnumFacing;
import net.minecraft.util.ResourceLocation;
import net.minecraft.world.World;
import net.minecraftforge.fml.relauncher.Side;
import net.minecraftforge.fml.relauncher.SideOnly;

import javax.annotation.Nonnull;
import javax.annotation.Nullable;
import java.util.*;
import java.util.concurrent.atomic.AtomicInteger;
import java.util.stream.Collectors;

import static gregtech.api.GTValues.*;

public class EPMetaTileEntityQuantumForceTransformer extends RecipeMapMultiblockController {

    private int ManipulatorCasingTier;
    private int ShieldingCoreCasingTier;
    private int tier;
    private static boolean init = false;
    private static List<IBlockState> finalListManipulatorCasing;
    private static List<IBlockState> finalListShieldingCoreCasing;

    public EPMetaTileEntityQuantumForceTransformer(ResourceLocation metaTileEntityId) {
        super(metaTileEntityId, EPRecipeMaps.QUANTUM_FORCE_TRANSFORMER_RECIPES);
        initMap();
    }

    @Override
    public MetaTileEntity createMetaTileEntity(IGregTechTileEntity iGregTechTileEntity) {
        return new EPMetaTileEntityQuantumForceTransformer(metaTileEntityId);
    }

    private void initMap() {
        if (init) return;

        List<IBlockState> ListManipulatorCasing = EPAPI.MAP_QFT_MANIPULATOR.entrySet().stream()
                .sorted(Comparator.comparingInt(entry -> ((WrappedIntTier) entry.getValue()).getIntTier()))
                .map(Map.Entry::getKey)
                .collect(Collectors.toList());

        List<IBlockState> ListShieldingCoreCasing = EPAPI.MAP_QFT_SHIELDING_CORE.entrySet().stream()
                .sorted(Comparator.comparingInt(entry -> ((WrappedIntTier) entry.getValue()).getIntTier()))
                .map(Map.Entry::getKey)
                .collect(Collectors.toList());

        int maxLeng = EPUniverUtil.maxLength(new ArrayList<List<IBlockState>>() {{
            add(ListManipulatorCasing);
            add(ListShieldingCoreCasing);
        }});

        finalListManipulatorCasing = EPUniverUtil.consistentList(ListManipulatorCasing, maxLeng);
        finalListShieldingCoreCasing = EPUniverUtil.consistentList(ListShieldingCoreCasing, maxLeng);

        init = true;
    }

    @Override
    protected void formStructure(PatternMatchContext context) {
        super.formStructure(context);
        Object ManipulatorCasingTier = context.get("QFTManipulatorCasingTieredStats");
        Object ShieldingCoreCasingTier = context.get("QFTShieldingCoreCasingTieredStats");

        this.ManipulatorCasingTier = EPUniverUtil.getOrDefault(() -> ManipulatorCasingTier instanceof WrappedIntTier,
                () -> ((WrappedIntTier) ManipulatorCasingTier).getIntTier(), 0);
        this.ShieldingCoreCasingTier = EPUniverUtil.getOrDefault(() -> ShieldingCoreCasingTier instanceof WrappedIntTier,
                () -> ((WrappedIntTier) ShieldingCoreCasingTier).getIntTier(), 0);

        this.tier = this.ManipulatorCasingTier = this.ShieldingCoreCasingTier;

        this.writeCustomData(EPDataCode.EP_CHANNEL_8, buf -> buf.writeInt(this.ManipulatorCasingTier));
    }

    @Override
    public void update() {
        super.update();

        if (this.getWorld().isRemote && this.ManipulatorCasingTier == 0) {
            this.writeCustomData(EPDataCode.EP_CHANNEL_9, buf -> {});
        }
    }

    @SuppressWarnings("SpellCheckingInspection")
    @Nonnull
    @Override
    protected BlockPattern createStructurePattern() {
        return FactoryBlockPattern.start()
                .aisle("    A     A    ", "    A     A    ", "    A     A    ", "   BA     AB   ", "   BABBABBAB   ", "   BAAAAAAAB   ", "   BBBBABBBB   ", "      BAB      ", "               ", "               ", "               ", "               ", "               ", "               ", "               ", "               ", "               ", "               ", "               ", "               ", "               ")
                .aisle("               ", "               ", "               ", "  A         A  ", "  A         A  ", "  B         B  ", "  BAAAAAAAAAB  ", "   AAABBBAAA   ", "      BAB      ", "               ", "               ", "               ", "               ", "               ", "               ", "               ", "               ", "               ", "               ", "               ", "               ")
                .aisle("               ", "               ", "               ", " A           A ", " A           A ", " B           B ", " BAA       AAB ", "  AA       AA  ", "    AA   AA    ", "      BAB      ", "               ", "               ", "               ", "               ", "               ", "               ", "               ", "               ", "               ", "               ", "               ")
                .aisle("A             A", "A             A", "A             A", "A             A", "A             A", "B             B", "BAA         AAB", " AA         AA ", "   AA     AA   ", "     BAAAB     ", "               ", "               ", "               ", "               ", "               ", "               ", "               ", "               ", "               ", "               ", "               ")
                .aisle("      HHH      ", "      EEE      ", "      EEE      ", "      EEE      ", "B     DDD     B", "B     EEE     B", "BA    DDD    AB", " A    EEE    A ", "  AA  EEE  AA  ", "    BAEEEAB    ", "      DDD      ", "      EEE      ", "      EEE      ", "      EEE      ", "      DDD      ", "      EEE      ", "      DDD      ", "      EEE      ", "      EEE      ", "      EEE      ", "      HHH      ")
                .aisle("     HHHHH     ", "     ECCCE     ", "     ECCCE     ", "B    ECCCE    B", "B    D   D    B", "B    ECCCE    B", "BA   D   D   AB", " A   ECCCE   A ", "  A  ECCCE  A  ", "   BAECCCEAB   ", "     D   D     ", "     ECCCE     ", "     ECCCE     ", "     ECCCE     ", "     D   D     ", "     ECCCE     ", "     D   D     ", "     ECCCE     ", "     ECCCE     ", "     ECCCE     ", "     HHHHH     ")
                .aisle("    HHHHHHH    ", "    EC   CE    ", "A   EC   CE   A", "A   EC   CE   A", "A   D     D   A", "A   EC   CE   A", "BA  D     D  AB", "BB  EC   CE  BB", " B  EC   CE  B ", "  BAEC   CEAB  ", "    D     D    ", "    EC   CE    ", "    EC   CE    ", "    EC   CE    ", "    D     D    ", "    EC   CE    ", "    D     D    ", "    EC   CE    ", "    EC   CE    ", "    ECCCCCE    ", "    HHHHHHH    ")
                .aisle("    HHHHHHH    ", "    EC   CE    ", "    EC   CE    ", "    EC   CE    ", "A   D     D   A", "A   EC   CE   A", "AA  D     D  AA", "AB  EC   CE  BA", " A  EC   CE  A ", "  AAEC   CEAA  ", "    D     D    ", "    EC   CE    ", "    EC   CE    ", "    EC   CE    ", "    D     D    ", "    EC   CE    ", "    D     D    ", "    EC   CE    ", "    EC   CE    ", "    ECCCCCE    ", "    HHHHHHH    ")
                .aisle("    HHHHHHH    ", "    EC   CE    ", "    EC   CE    ", "A   EC   CE   A", "A   D     D   A", "A   EC   CE   A", "BA  D     D  AB", "BB  EC   CE  BB", " B  EC   CE  B ", "  BAEC   CEAB  ", "    D     D    ", "    EC   CE    ", "    EC   CE    ", "    EC   CE    ", "    D     D    ", "    EC   CE    ", "    D     D    ", "    EC   CE    ", "    EC   CE    ", "    ECCCCCE    ", "    HHHHHHH    ")
                .aisle("     HHHHH     ", "     ECCCE     ", "     ECCCE     ", "B    ECCCE    B", "B    D   D    B", "B    ECCCE    B", "BA   D   D   AB", " A   ECCCE   A ", "  A  ECCCE  A  ", "   BAECCCEAB   ", "     D   D     ", "     ECCCE     ", "     ECCCE     ", "     ECCCE     ", "     D   D     ", "     ECCCE     ", "     D   D     ", "     ECCCE     ", "     ECCCE     ", "     ECCCE     ", "     HHHHH     ")
                .aisle("      HSH      ", "      EEE      ", "      EEE      ", "      EEE      ", "B     DDD     B", "B     EEE     B", "BA    DDD    AB", " A    EEE    A ", "  AA  EEE  AA  ", "    BAEEEAB    ", "      DDD      ", "      EEE      ", "      EEE      ", "      EEE      ", "      DDD      ", "      EEE      ", "      DDD      ", "      EEE      ", "      EEE      ", "      EEE      ", "      HHH      ")
                .aisle("A             A", "A             A", "A             A", "A             A", "A             A", "B             B", "BAA          AB", " AA         AA ", "   AA     AA   ", "     BAAAB     ", "               ", "               ", "               ", "               ", "               ", "               ", "               ", "               ", "               ", "               ", "               ")
                .aisle("               ", "               ", "               ", " A           A ", " A           A ", " B           B ", " BA         AB ", "  AA       AA  ", "    AA   AA    ", "      BAB      ", "               ", "               ", "               ", "               ", "               ", "               ", "               ", "               ", "               ", "               ", "               ")
                .aisle("               ", "               ", "               ", "  A         A  ", "  A         A  ", "  B         B  ", "  BAAAAAAAAAB  ", "   AAABBBAAA   ", "      BAB      ", "               ", "               ", "               ", "               ", "               ", "               ", "               ", "               ", "               ", "               ", "               ", "               ")
                .aisle("    A     A    ", "    A     A    ", "    A     A    ", "   BA     AB   ", "   BABBABBAB   ", "   BAAAAAAAB   ", "   BBBBABBBB   ", "      BAB      ", "               ", "               ", "               ", "               ", "               ", "               ", "               ", "               ", "               ", "               ", "               ", "               ", "               ")
                .where('S', this.selfPredicate())
                .where('A', EPTraceabilityPredicate.EP_QFT_MANIPULATOR.get())
                .where('B', EPTraceabilityPredicate.EP_QFT_SHIELDING_CORE.get())
                .where('C', states(getCoilState()))
                .where('D', states(getCasingState()))
                .where('E', states(getGlassState()))
                .where('H', states(getCasingState())
                        .setMinGlobalLimited(55)
                        .or(autoAbilities()))
                .build();
    }

    private IBlockState getCasingState() {
        return EPMetablocks.EP_QUANTUM_FORCE_TRANSFORMER_CASING.getState(EPBlockQuantumForceTransformerCasing.CasingType.QUANTUM_CONSTRAINT_CASING);
    }

    private IBlockState getGlassState() {
        return EPMetablocks.EP_GLASS_CASING_B.getState(EPBlockGlassCasingB.GlassType.INFINITY_GLASS);
    }

    private IBlockState getCoilState() {
        return EPMetablocks.EP_QUANTUM_FORCE_TRANSFORMER_CASING.getState(EPBlockQuantumForceTransformerCasing.CasingType.QUANTUM_FORCE_TRANSFORMER_COIL);
    }

    @SideOnly(Side.CLIENT)
    @Nonnull
    @Override
    protected ICubeRenderer getFrontOverlay() {
        return EPTextures.CHEMICAL_PLANT_OVERLAY;
    }

    @SideOnly(Side.CLIENT)
    @Override
    public ICubeRenderer getBaseTexture(IMultiblockPart iMultiblockPart) {
        return EPTextures.QUANTUM_CONSTRAINT_CASING;
    }

    @Override
    public List<MultiblockShapeInfo> getMatchingShapes() {
        ArrayList<MultiblockShapeInfo> shapeInfo = new ArrayList<>();
        MultiblockShapeInfo.Builder builder = null;
        if (Blocks.AIR != null) {
            builder = MultiblockShapeInfo.builder()
                    .aisle("    A     A    ", "    A     A    ", "    A     A    ", "   BA     AB   ", "   BABBABBAB   ", "   BAAAAAAAB   ", "   BBBBABBBB   ", "      BAB      ", "               ", "               ", "               ", "               ", "               ", "               ", "               ", "               ", "               ", "               ", "               ", "               ", "               ")
                    .aisle("               ", "               ", "               ", "  A         A  ", "  A         A  ", "  B         B  ", "  BAAAAAAAAAB  ", "   AAABBBAAA   ", "      BAB      ", "               ", "               ", "               ", "               ", "               ", "               ", "               ", "               ", "               ", "               ", "               ", "               ")
                    .aisle("               ", "               ", "               ", " A           A ", " A           A ", " B           B ", " BAA       AAB ", "  AA       AA  ", "    AA   AA    ", "      BAB      ", "               ", "               ", "               ", "               ", "               ", "               ", "               ", "               ", "               ", "               ", "               ")
                    .aisle("A             A", "A             A", "A             A", "A             A", "A             A", "B             B", "BAA         AAB", " AA         AA ", "   AA     AA   ", "     BAAAB     ", "               ", "               ", "               ", "               ", "               ", "               ", "               ", "               ", "               ", "               ", "               ")
                    .aisle("      WXH      ", "      EEE      ", "      EEE      ", "      EEE      ", "B     DDD     B", "B     EEE     B", "BA    DDD    AB", " A    EEE    A ", "  AA  EEE  AA  ", "    BAEEEAB    ", "      DDD      ", "      EEE      ", "      EEE      ", "      EEE      ", "      DDD      ", "      EEE      ", "      DDD      ", "      EEE      ", "      EEE      ", "      EEE      ", "      TTT      ")
                    .aisle("     HHHHH     ", "     ECCCE     ", "     ECCCE     ", "B    ECCCE    B", "B    D   D    B", "B    ECCCE    B", "BA   D   D   AB", " A   ECCCE   A ", "  A  ECCCE  A  ", "   BAECCCEAB   ", "     D   D     ", "     ECCCE     ", "     ECCCE     ", "     ECCCE     ", "     D   D     ", "     ECCCE     ", "     D   D     ", "     ECCCE     ", "     ECCCE     ", "     ECCCE     ", "     TTTTT     ")
                    .aisle("    HHHHHHH    ", "    EC   CE    ", "A   EC   CE   A", "A   EC   CE   A", "A   D     D   A", "A   EC   CE   A", "BA  D     D  AB", "BB  EC   CE  BB", " B  EC   CE  B ", "  BAEC   CEAB  ", "    D     D    ", "    EC   CE    ", "    EC   CE    ", "    EC   CE    ", "    D     D    ", "    EC   CE    ", "    D     D    ", "    EC   CE    ", "    EC   CE    ", "    ECCCCCE    ", "    TTTTTTT    ")
                    .aisle("    UHHHHHV    ", "    EC   CE    ", "    EC   CE    ", "    EC   CE    ", "A   D     D   A", "A   EC   CE   A", "AA  D     D  AA", "AB  EC   CE  BA", " A  EC   CE  A ", "  AAEC   CEAA  ", "    D     D    ", "    EC   CE    ", "    EC   CE    ", "    EC   CE    ", "    D     D    ", "    EC   CE    ", "    D     D    ", "    EC   CE    ", "    EC   CE    ", "    ECCCCCE    ", "    TTTTTTT    ")
                    .aisle("    HHHHHHH    ", "    EC   CE    ", "    EC   CE    ", "A   EC   CE   A", "A   D     D   A", "A   EC   CE   A", "BA  D     D  AB", "BB  EC   CE  BB", " B  EC   CE  B ", "  BAEC   CEAB  ", "    D     D    ", "    EC   CE    ", "    EC   CE    ", "    EC   CE    ", "    D     D    ", "    EC   CE    ", "    D     D    ", "    EC   CE    ", "    EC   CE    ", "    ECCCCCE    ", "    TTTTTTT    ")
                    .aisle("     HHHHH     ", "     ECCCE     ", "     ECCCE     ", "B    ECCCE    B", "B    D   D    B", "B    ECCCE    B", "BA   D   D   AB", " A   ECCCE   A ", "  A  ECCCE  A  ", "   BAECCCEAB   ", "     D   D     ", "     ECCCE     ", "     ECCCE     ", "     ECCCE     ", "     D   D     ", "     ECCCE     ", "     D   D     ", "     ECCCE     ", "     ECCCE     ", "     ECCCE     ", "     TTTTT     ")
                    .aisle("      YSZ      ", "      EEE      ", "      EEE      ", "      EEE      ", "B     DDD     B", "B     EEE     B", "BA    DDD    AB", " A    EEE    A ", "  AA  EEE  AA  ", "    BAEEEAB    ", "      DDD      ", "      EEE      ", "      EEE      ", "      EEE      ", "      DDD      ", "      EEE      ", "      DDD      ", "      EEE      ", "      EEE      ", "      EEE      ", "      TTT      ")
                    .aisle("A             A", "A             A", "A             A", "A             A", "A             A", "B             B", "BAA          AB", " AA         AA ", "   AA     AA   ", "     BAAAB     ", "               ", "               ", "               ", "               ", "               ", "               ", "               ", "               ", "               ", "               ", "               ")
                    .aisle("               ", "               ", "               ", " A           A ", " A           A ", " B           B ", " BA         AB ", "  AA       AA  ", "    AA   AA    ", "      BAB      ", "               ", "               ", "               ", "               ", "               ", "               ", "               ", "               ", "               ", "               ", "               ")
                    .aisle("               ", "               ", "               ", "  A         A  ", "  A         A  ", "  B         B  ", "  BAAAAAAAAAB  ", "   AAABBBAAA   ", "      BAB      ", "               ", "               ", "               ", "               ", "               ", "               ", "               ", "               ", "               ", "               ", "               ", "               ")
                    .aisle("    A     A    ", "    A     A    ", "    A     A    ", "   BA     AB   ", "   BABBABBAB   ", "   BAAAAAAAB   ", "   BBBBABBBB   ", "      BAB      ", "               ", "               ", "               ", "               ", "               ", "               ", "               ", "               ", "               ", "               ", "               ", "               ", "               ")
                    .where('S', EPMetaTileEntities.QUANTUM_FORCE_TRANSFORMER, EnumFacing.SOUTH)
                    .where('X', MetaTileEntities.ENERGY_INPUT_HATCH[UHV], EnumFacing.NORTH)
                    .where('Y', MetaTileEntities.FLUID_IMPORT_HATCH[UHV], EnumFacing.SOUTH)
                    .where('Z', MetaTileEntities.FLUID_EXPORT_HATCH[UHV], EnumFacing.SOUTH)
                    .where('U', MetaTileEntities.ITEM_IMPORT_BUS[UHV], EnumFacing.WEST)
                    .where('V', MetaTileEntities.ITEM_EXPORT_BUS[UHV], EnumFacing.EAST)
                    .where('W', MetaTileEntities.MAINTENANCE_HATCH, EnumFacing.NORTH)
                    .where('C', getCoilState())
                    .where('D', getCasingState())
                    .where('E', getGlassState())
                    .where('H', getCasingState())
                    .where('T', getCasingState())
                    .where(' ', Blocks.AIR.getDefaultState());
        }
        MultiblockShapeInfo.Builder finalBuilder = builder;
        AtomicInteger count = new AtomicInteger();
        finalListManipulatorCasing.stream()
                .map(b -> {
                    if (finalBuilder != null) {
                        finalBuilder.where('A', b);
                        finalBuilder.where('B', finalListShieldingCoreCasing.get(count.get()));
                        count.getAndIncrement();
                    }
                    return finalBuilder;
                })
                .filter(Objects::nonNull)
                .forEach(b -> shapeInfo.add(b.build()));
        return shapeInfo;
    }

    @Override
    public void receiveCustomData(int dataId, PacketBuffer buf) {
        super.receiveCustomData(dataId, buf);
        if (dataId == EPDataCode.EP_CHANNEL_8) {
            this.ManipulatorCasingTier = buf.readInt();
        }
        if (dataId == EPDataCode.EP_CHANNEL_9) {
            this.writeCustomData(EPDataCode.EP_CHANNEL_8, buf1 -> buf1.writeInt(this.ManipulatorCasingTier));
        }
    }

    @Override
    public void writeInitialSyncData(PacketBuffer buf) {
        super.writeInitialSyncData(buf);
        buf.writeInt(this.ManipulatorCasingTier);
    }

    @Override
    public void receiveInitialSyncData(PacketBuffer buf) {
        super.receiveInitialSyncData(buf);
        this.ManipulatorCasingTier = buf.readInt();
    }

    @Override
    public void addInformation(ItemStack stack, @Nullable World player, List<String> tooltip, boolean advanced) {
        super.addInformation(stack, player, tooltip, advanced);
        tooltip.add(I18n.format("epimorphism.machine.quantum_force_transformer.tooltip.1"));
        tooltip.add(I18n.format("epimorphism.machine.quantum_force_transformer.tooltip.2"));
        tooltip.add(I18n.format("epimorphism.machine.quantum_force_transformer.tooltip.3"));
    }
}
